Workbook

Sheet graph
A1: =SUMMARY!A4 -> Year | B1: =SUMMARY!C4 -> No. of Incidents | C1: =SUMMARY!D4 -> Volume (cu.m.) | D1: Value (Php)
A2: 2014 | B2: =SUMMARY!C82 -> 88 | C2: =SUMMARY!D82 -> 186.87249 | D2: =SUMMARY!F82 -> 2142713.3
A3: 2015 | B3: =SUMMARY!C76 -> 0 | C3: =SUMMARY!D76 -> 0 | D3: =SUMMARY!F76 -> 0
A4: 2016 | B4: =SUMMARY!C70 -> 0 | C4: =SUMMARY!D70 -> 0 | D4: =SUMMARY!F70 -> 0
A5: 2017 | B5: =SUMMARY!C64 -> 0 | C5: =SUMMARY!D64 -> 0 | D5: =SUMMARY!F64 -> 0
A6: 2018 | B6: =SUMMARY!C58 -> 0 | C6: =SUMMARY!D58 -> 0 | D6: =SUMMARY!F58 -> 0
A7: 2019 | B7: =SUMMARY!C52 -> 0 | C7: =SUMMARY!D52 -> 0 | D7: =SUMMARY!F52 -> 0
A8: 2020 | B8: =SUMMARY!C46 -> 0 | C8: =SUMMARY!D46 -> 0 | D8: =SUMMARY!F46 -> 0
A9: 2021 | B9: =SUMMARY!C40 -> 0 | C9: =SUMMARY!D40 -> 0 | D9: =SUMMARY!F40 -> 0
A10: 2022 | B10: =SUMMARY!C34 -> 96 | C10: =SUMMARY!D34 -> 93.781698 | D10: =SUMMARY!F34 -> 1621287.7
A11: 2023 | B11: =SUMMARY!C28 -> 111 | C11: =SUMMARY!D28 -> 88.1727 | D11: =SUMMARY!F28 -> 2125759
A12: 2024 | B12: =SUMMARY!C22 -> 116 | C12: =SUMMARY!D22 -> 65.944958 | D12: =SUMMARY!F22 -> 2119779.5
A13: 2025 | B13: =SUMMARY!C16 -> 83 | C13: =SUMMARY!D16 -> 193.047 | D13: =SUMMARY!F16 -> 2847280.8
A14: 2026 | B14: =SUMMARY!C10 -> 112 | C14: =SUMMARY!D10 -> 710.4452 | D14: =SUMMARY!F10 -> 1880415.9

Sheet SUMMARY
A1: SUMMARY OF APPREHENDED, SEIZED AND CONFISCATED FOREST PRODUCTS
A2: PROVINCE OF CAGAYAN — BY YEAR AND CENRO
A4: Year | B4: CENRO | C4: No. of Incidents | D4: Volume (cu.m.) | E4: Volume (bd.ft.) | F4: Estimated Value (PHP) | G4: NO. OF CONVEYANCE | H4: ESTIMATED VALUE | I4: NO. OF EQUIPMENTS | J4: ESTIMATED VALUE
A5: 2026 | B5: Cenro Aparri | C5: =COUNTA('2026'!B10:B53) -> 43 | D5: ='2026'!G54 -> 104.42 | E5: =SUM('2026'!H10:H53) -> 12721.54 | F5: ='2026'!I54 -> 1052210.6
B6: Cenro Alcala | C6: =COUNTA('2026'!B56:B84) -> 29 | D6: ='2026'!G85 -> 589.61 | E6: =SUM('2026'!H56:H84) -> 5421.896 | F6: ='2026'!I85 -> 394948.6
B7: Cenro Solana | C7: =COUNTA('2026'!B87:B105) -> 19 | D7: =SUM('2026'!G87:G105) -> 11.49 | E7: =SUM('2026'!H87:H105) -> 6738.18 | F7: ='2026'!I106 -> 320432.95
B8: Cenro Sanchez Mira | C8: =COUNTA('2026'!B108:B121) -> 14 | D8: =SUM('2026'!G108:G121) -> 2.937 | E8: ='2026'!H122 -> 1247.1 | F8: ='2026'!I122 -> 100823.72
B9: Cenro Sub Office | C9: =COUNTA('2026'!B124:B130) -> 7 | D9: =SUM('2026'!G124:G130) -> 1.9882 | E9: ='2026'!H131 -> 1704.07 | F9: ='2026'!I131 -> 12000
A10: =concat(A5," TOTAL") -> 2026 TOTAL | C10: =sum(C5:C9) -> 112 | D10: =sum(D5:D9) -> 710.4452 | E10: =sum(E5:E9) -> 27832.786 | F10: =sum(F5:F9) -> 1880415.9
A11: 2025 | B11: Cenro Aparri | C11: =COUNTA('2025'!A6:A58) -> 53 | D11: ='2025'!G59 -> 121.297 | E11: ='2025'!H59 -> 51828.843 | F11: ='2025'!I59 -> 2756760.8
B12: Cenro Alcala | C12: =COUNTA('2025'!A61:A68) -> 8 | D12: - | E12: ='2025'!H69 -> 1236.3 | F12: ='2025'!I69 -> 90520
B13: Cenro Solana | C13: ='2025'!A91 -> 13 | D13: ='2025'!G91 -> 8.75 | E13: ='2025'!H91 -> 10977.62 | F13: -
B14: Cenro Sanchez Mira | C14: ='2025'!A76 -> 5 | D14: - | E14: ='2025'!H76 -> 2740.99 | F14: -
B15: Cenro Sub Office | C15: ='2025'!A97 -> 4 | D15: ='2025'!G97 -> 63 | E15: ='2025'!H97 -> 60 | F15: -
A16: =concat(A11," TOTAL") -> 2025 TOTAL | C16: =SUM(C11:C15) -> 83 | D16: =SUM(D11:D15) -> 193.047 | E16: =SUM(E11:E15) -> 66843.753 | F16: =SUM(F11:F15) -> 2847280.8
A17: 2024 | B17: Cenro Aparri | C17: ='2024'!A36 -> 29 | D17: ='2024'!G36 -> 20.061297 | E17: ='2024'!H36 -> 8765.83 | F17: ='2024'!I36 -> 521740.95
B18: Cenro Alcala | C18: ='2024'!A81 -> 43 | D18: ='2024'!G81 -> 15.528 | E18: ='2024'!H81 -> 8775 | F18: ='2024'!I81 -> 459125
B19: Cenro Solana | C19: ='2024'!A110 -> 27 | D19: ='2024'!G110 -> 24.51 | E19: ='2024'!H110 -> 11082.91 | F19: ='2024'!I110 -> 616751
B20: Cenro Sanchez Mira | C20: ='2024'!A124 -> 12 | D20: ='2024'!G124 -> 4.6356604 | E20: ='2024'!H124 -> 3913.47 | F20: ='2024'!I124 -> 483402.5
B21: Cenro Sub Office | C21: ='2024'!A131 -> 5 | D21: ='2024'!G131 -> 1.21 | E21: ='2024'!H131 -> 1302.03 | F21: ='2024'!I131 -> 38760
A22: =concat(A17," TOTAL") -> 2024 TOTAL | C22: =SUM(C17:C21) -> 116 | D22: =SUM(D17:D21) -> 65.944958 | E22: =SUM(E17:E21) -> 33839.24 | F22: =SUM(F17:F21) -> 2119779.5
A23: 2023 | B23: Cenro Aparri | C23: ='2023'!A42 -> 36 | D23: ='2023'!G42 -> 31.973 | E23: ='2023'!H42 -> 14086.73 | F23: ='2023'!I42 -> 765301.4
B24: Cenro Alcala | C24: ='2023'!A78 -> 34 | D24: ='2023'!G78 -> 15.705 | E24: ='2023'!H78 -> 9795.55 | F24: ='2023'!I78 -> 381980
B25: Cenro Solana | C25: ='2023'!A103 -> 22 | D25: ='2023'!G103 -> 19.846 | E25: ='2023'!H103 -> 9725.02 | F25: ='2023'!I103 -> 469687.5
B26: Cenro Sanchez Mira | C26: ='2023'!A131 -> 19 | D26: ='2023'!G131 -> 20.6487 | E26: ='2023'!H131 -> 8755.89 | F26: ='2023'!I131 -> 508790.05
B27: Cenro Sub Office | C27: - | D27: - | E27: - | F27: -
A28: =concat(A23," TOTAL") -> 2023 TOTAL | C28: =SUM(C23:C27) -> 111 | D28: =SUM(D23:D27) -> 88.1727 | E28: =SUM(E23:E27) -> 42363.19 | F28: =SUM(F23:F27) -> 2125759
A29: 2022 | B29: Cenro Aparri | C29: ='2022'!A47 -> 35 | D29: ='2022'!F47 -> 21.087689 | E29: - | F29: ='2022'!H47 -> 395666.41
B30: Cenro Alcala | C30: ='2022'!A70 -> 21 | D30: ='2022'!F70 -> 29.42166 | E30: - | F30: ='2022'!H70 -> 516242
B31: Cenro Solana | C31: ='2022'!A90 -> 17 | D31: ='2022'!F90 -> 13.661708 | E31: - | F31: ='2022'!H90 -> 241684.3
B32: Cenro Sanchez Mira | C32: ='2022'!A115 -> 23 | D32: ='2022'!F115 -> 29.610642 | E32: - | F32: ='2022'!H115 -> 467694.97
B33: Cenro Sub Office
A34: =concat(A29," TOTAL") -> 2022 TOTAL | C34: =SUM(C29:C33) -> 96 | D34: =SUM(D29:D33) -> 93.781698 | E34: =SUM(E29:E33) -> 0 | F34: =SUM(F29:F33) -> 1621287.7
A35: 2021 | B35: Cenro Aparri
B36: Cenro Alcala
B37: Cenro Solana
B38: Cenro Sanchez Mira
B39: Cenro Sub Office
A40: =concat(A35," TOTAL") -> 2021 TOTAL | C40: =SUM(C35:C39) -> 0 | D40: =SUM(D35:D39) -> 0 | E40: =SUM(E35:E39) -> 0 | F40: =SUM(F35:F39) -> 0
A41: 2020 | B41: Cenro Aparri
...

Sheet 2014
B1: CONSOLIDATED APPREHENDED, SEIZED AND CONFISCATED FOREST PRODUCTS
B2: PROVINCE OF CAGAYAN
B3: Calendar Year 2014
B5: Date & Place of apprehension/ seizure & confiscation | C5: Circumstances of apprehension/ seizure & confiscation (e.g. no permit, or accompanying documents, etc.) | D5: Description of Forest Products | G5: Place Stockpiled and Custodian with complete address | H5: Other agencies involved in the apprehension/ seizure & confiscation (Names of personnel, LGUs, etc.) | I5: Other remarks (condition, status of criminal complaint if any, etc.)
D6: Quantity (# of pcs.) and form (lumber, logs, flitches, split/unsplit rattan, etc.) | E6: VOLUME (CU.M.) | F6: Estimated Market Value (PhP)
A7: No. | B7: CENRO TUGUEGARAO
A8: 1 | B8: January 17, 2014/ Danna, Manga, Peñablanca, Cag. | C8: No claimant | D8: 3 pcs. Narra flitches | E8: =146/424 -> 0.34433962 | F8: 11680 | G8: CENRO compound | I8: Confiscated in favor of the government dated April 3, 2014
A9: 2 | B9: January 25, 2014/ Lalongan, Sisim, Peñablanca, Cagayan | C9: No claimant | D9: 203 CHW lumber | E9: =1334.66/424 -> 3.147783 | F9: 46713.1 | G9: CENRO compound | I9: Confiscated in favor of the gov't. per order of the RED dated March 17, 2014. A total of 650.66 bd.ft./1.53 cu.m. was donated to the Provincial Capitol.
A10: 3 | B10: February 5, 2014/ Pinacanauan River, Camasi, Peñablanca, Cag. | C10: No claimant | D10: 60 pcs. CHW lumber | E10: =1112/424 -> 2.6226415 | F10: 38920 | G10: Camasi Brgy. Hall, Peñablanca, Cag./ Chairwoman Zenaida Leones | H10: BLGU Camasi, Peñablanca, Cag. Headed by Chairwoman Zenaida Leones | I10: Confiscated in favor of the government dated June 10, 2014
A11: 4 | B11: February 13, 2014/ Don Domingo, Balzain, Tuguegarao City | C11: No claimant | D11: 80 Sacks of charcoal | F11: 16000 | G11: CENRO compound | I11: Confiscated in favor of the government dated May 7, 2014. The 20 sacks of charcoal was donated at the Feeding Center of San Esteban, Iguig, Cag.
A12: 5 | B12: February 19, 2014/ Pinacanauan River, Barangay Lapi, Peñablanca, Cag. | C12: No claimant | D12: 14 pcs. Narra lumber | E12: =172.16/424 -> 0.40603774 | F12: 10329.6 | G12: CENRO compound | I12: Confiscated in favor of the government dated April 30, 2014
A13: 6 | B13: February 23, 2014/ San Roque, Peñablanca, Cag. | C13: No claimant | D13: 4 pcs. CHW lumber | E13: =128/424 -> 0.30188679 | F13: 3840 | G13: Brgy. Hall San Roque, Peñablanca, Cag./ Brgy. Captain Benjamin Tumbali | H13: Barangay Officials of San Roque, Peñablanca, Cag. Headed by Brgy Captain Benjamin Tumbali | I13: Confiscated in favor of the government dated May 23, 2014
A14: 7 | B14: March 7, 2014/ Libag, Tuguegarao City | C14: No permit/ transport documents (ZGJ-637) | D14: 95 pcs. CHW lumber | E14: =665/424 -> 1.5683962 | F14: 23275 | G14: CENRO compound | I14: Both conveyance and the forest products was ordered confiscated in favor of the government dated August 12, 2015
A15: 8 | B15: March 11, 2014/ Capatan, Tuguegarao City | C15: No claimant | D15: 8 Sacks of charcoal | F15: 1600 | G15: CENRO compound | I15: Confiscated in favor of the government dated May 20, 2014
A16: 9 | B16: March 12, 2014/ NAPOCOR Peñablanca, Cag. | C16: No claimant | D16: 15 Sacks of charcoal | F16: 3000 | G16: CENRO compound | I16: Confiscated in favor of the government dated May 20, 2014
A17: 10 | B17: March 13, 2014/ Dodan, Peñablanca, Cag. | C17: No claimant | D17: 5 Sacks of charcoal | F17: 1000 | G17: CENRO compound | I17: Confiscated in favor of the government dated May 20, 2014
A18: 11 | B18: April 17, 2014/ Nanarian, Peñablanca, Cag. | C18: No claimant | D18: 12 CHW lumber | E18: 0.33 | F18: 4900 | G18: CENRO compound | I18: Confiscated in favor of the government dated June 3, 2014
A19: 12 | B19: April 26, 2014/ Sisim Peñablanca, Cag. | C19: No claimant | D19: 1 pc. Tindalo Lbr. | E19: 0.16 | F19: 5600 | G19: CENRO compound | I19: Confiscated in favor of the gov't. dated June 3, 2014
A20: 13 | D20: 3 pcs. Narra lbr. | E20: 0.32 | F20: 10666 | G20: CENRO compound
A21: 14 | B21: July 20, 2014/ Dodan, Peñablanca, Cagayan | C21: No claimant | D21: 7 pcs. Tuai lumber | E21: =110.66/424 -> 0.26099057 | F21: 3813.1 | G21: CENRO compound | I21: Under administrative adjudication proceedings. With Order of Finality received on Dec. 09, 2024 promulgated on Oct. 16, 2014 with Docket No. R2-F-1036
A22: 15 | B22: August 3, 2014/ Quibal, Peñablanca, Cag. | C22: No claimant | D22: 30 pcs. CHW lumber | E22: =316/424 -> 0.74528302 | F22: 11060 | G22: CENRO compound | I22: Confiscated in favor of the government per order dated Dec. 10, 2014
A23: 16 | B23: Bical, Peñablanca, Cag. | C23: No claimant | D23: 20 sacks of charcoal | F23: =200*20 -> 4000 | G23: CENRO compound | H23: Barangay Officials of Bical, Peñablanca, Cag. | I23: Under administrative adjudication proceedings
A24: 17 | B24: August 5, 2014/ Baliuag, Peñablanca, Cag. | C24: No claimant | D24: 50 Sacks of charcoal | F24: 10000 | G24: CENRO compound | H24: Barangay Officials of Baliuag, Penablanca, Cag. | I24: Confiscated in favor of the government per order dated Sept. 30, 2014
A25: 18 | B25: August 16, 2014/ Quibal, Peñablanca, Cag. | C25: No claimant | D25: 33 CHW lumber | E25: =260/424 -> 0.61320755 | F25: 9100 | G25: CENRO compound | I25: Confiscated in favor of the government per order dated Sept. 30, 2014
A26: 19 | B26: September 11, 2014/ Dodan, Peñablanca, Cag. | C26: No claimant | D26: 32 CHW lumber | E26: =601/424 -> 1.4174528 | F26: 21046 | G26: CENRO compound | I26: Confiscated in favor of the government per order dated Dec. 10, 2014. Order final and executory dated March 28, 2021
A27: 20 | B27: September 25, 2014/ San Roque, Peñablanca, Cag. | C27: No claimant | D27: 46 pcs. CHW lumber | E27: =436/424 -> 1.0283019 | F27: 15260 | G27: CENRO compound | H27: Police Provincial Office | I27: Confiscated in favor of the government per order dated Jan. 10, 2015
A28: 21 | B28: September 29, 2014/ Capatan, Tuguegarao City | C28: No claimant | D28: 8 pcs. Gmelina and 4 pcs. Tuai flitches | E28: =199.58/424 -> 0.47070755 | F28: 6985.3 | G28: CENRO compound | I28: Under administrative adjudication proceedings
A29: =COUNTA(A8:A28) -> 21 | B29: SUB-TOTAL | E29: =SUM(E8:E28) -> 13.737028 | F29: =SUM(F8:F28) -> 258788.1
B30: CENRO APARRI
A31: 1 | B31: January 6, 2014/ Siwangag Cove, Palaui, San Vicente, Sta. Ana, Cag. | C31: No claimant (chainsaw/ handrill) | D31: 1 pc. Molave lumber & post | E31: 0.18 | F31: 4800 | G31: Naval Based/ Camilo Osias/ ENS Julius DN Villacarlos, PN | H31: Philippine Navy | I31: Under administrative adjudication proceedings
A32: 2 | B32: January 5, 2014/ Casambalangan, Sta. Ana, cag. | C32: CTU-567 | D32: 431 pcs. Old lumbers/ posts | E32: 7.38 | F32: 62582.4 | G32: CENRO compound | H32: PNP Regional Mobile Group | I32: The conveyance was released temporarily by posting a Cash Bond amounting to amounting to 60,000.00. Confiscated in favor of the government per undated order of the RED
A33: 3 | B33: February 13, 2014/ Macanaya, Aparri, Cag. | C33: BVT-300 | D33: 19 pcs. sacks charcoal | F33: 3230 | G33: CENRO compound | I33: The 19 sacks of charcoal was ordered confiscated in favor of the government while the conveyance was ordered to return in favor of the owner per order dated March 10, 2017.
A34: 4 | B34: February 14, 2014/ Agusi, Camalaniugan, Cag. | C34: (Kuliglig) | D34: 22 sacks of charcoal | F34: =170*22 -> 3740 | G34: CENRO compound | I34: Both conveyance anf forest products ordered confiscated in favor of the government dated June 6, 2014. With Order of Finality received on August 27, 2024
A35: 5 | B35: February 14, 2014/ Agusi, Camalaniugan, Cag. | C35: (Kuliglig) | D35: 37 sacks of charcoal | F35: =170*37 -> 6290 | G35: CENRO compound | I35: Both conveyance anf forest products ordered confiscated in favor of the government dated June 6, 2014
A36: 6 | B36: February 14, 2014/ Tallungan, Aparri, cag. | C36: (KB-509F428968) | D36: 16 sacks charcoal | F36: =170*16 -> 2720 | G36: CENRO compound | I36: The vehicle was ordered released in favor of the owner while the forest products confiscated in favor of the government per order dated June 26, 2014
A37: 7 | B37: February 19, 2014/ Sta. Clara, Sta. Ana, Cag. | C37: No claimant | D37: 442 pcs. CHW lumbers | E37: 4.77 | F37: 50575 | G37: CENRO compound | H37: PNP, LGU, CEZA, Pahilippine Navy | I37: Donated to Provincial Gov't. of Cagayan for the repair/ renovation of their office buildings
A38: 8 | B38: February 27, 2014/ Dumasag, Casambalangan, Sta. Ana, Cag. | C38: No claimant | D38: 7 pcs. CHW flitches | E38: 1.49 | F38: 12680 | G38: LGU Sta. Ana, Cag./ MENRO Florencio Obiano | H38: CEZA | I38: Confiscated in favor of the government dated May 23, 2014
A39: 9 | B39: March 8, 2014/ Sta. Clara, Gonzaga, cag. | C39: No permit/ transport documents (QH-1439) | D39: 37 pcs. CHW lumber | E39: 0.35 | F39: 3612.47 | G39: CENRO compound | H39: 77th IB Philippine Army headed by SSGT Rodolfo Cusapao | I39: For resolution
A40: 10 | B40: March 8, 2014/ Sta. Clara, Gonzaga, cag. | C40: No permit/ transport documents (TMX-155 No. Plate No.) | D40: 29 pcs. CHW lumber | E40: 0.31 | F40: 3134.2 | G40: CENRO compound | H40: 78th IB Philippine Army headed by SSGT Rodolfo Cusapao | I40: For resolution
A41: 11 | B41: March 9, 2014/ Aridowen, Sta. Teresita, Cag. | C41: No claimant | D41: 19 pcs. CHW lumber/logs | E41: 1.17 | F41: =10556+2418 -> 12974 | G41: CENRO compound | I41: Confiscated in favor of the government per order dated May 23, 2014
...

Sheet 2015
A1: CONSOLIDATED APPREHENDED, SEIZED AND CONFISCATED FOREST PRODUCTS
A2: PROVINCE OF CAGAYAN
A3: CALENDAR YEAR 2015
A5: Date & Place of apprehension/ seizure & confiscation | B5: Circumstances of apprehension/ seizure & confiscation (e.g. no permit, or accompanying documents, etc.) | C5: Description of Forest Products | G5: Place Stockpiled and Custodian with complete address | H5: Other agencies involved in the apprehension/ seizure & confiscation (Names of personnel, LGUs, etc.) | I5: Other remarks (condition, status of criminal complaint if any, etc.)
C6: Quantity (# of pcs.) and form (lumber, logs, flitches, split/unsplit rattan, etc.) | D6: VOLUME (CU.M.) | E6: VOLUME (bd.ft.) | F6: Estimated Market Value (PhP)
A7: CENRO APARRI
A8: Jan. 16, 2015/ Burubur, Magapit, Lal-lo, Cag. | B8: No permit/transport documents (WRD-139) | C8: 8 pcs. Narra flitches | D8: 0.738 | F8: 14096.25 | G8: CENRO Aparri compound/Edgar T. Martin | H8: 77th IB, 5th ID Bravo Coy Phil. Army | I8: Both forest products and the conveyance were ordered confiscated in favor of the government. The case filed against Darwin Calabiao was dismissed while the two (2) accused pleaded guilty for a lower offense, per Order dated March 9, 2015 of Presiding Judge Conrado T. Tabacco, TRC Branch 9, Aparri, Cag. Confiscated in favor of the government dated July 31, 2019. With Order of Finality received on Sept. 04, 2024
A9: February 7, 2015/Felipe Tuzon, Camalaniugan, Cagayan | B9: No permit (Froilan Fernando, Lope Esquiero, Junior Fernando, Bryan Padi, Jerwin Motay | C9: 18 pcs. Apitong poles | D9: =0.545 -> 0.545 | F9: 5775.19 | G9: CENRO Aparri compound/Edgar T. Martin | H9: PNP Camalaniugan, cag. | I9: Confiscated in favor of the government dated August 13, 2015. The case was filed against the 5 accused at the Office of the Provincial Prosecutor, Aparri, Cagayan on February 17, 2015 under NPS Docket No. II-02a-INV-158-00033.Order of finality date received January 8, 2025, date of promulgation August 13, 2015 with Docket no. R2-F-1105
A10: February 16, 2015/ Luga, Sta. Teresita, Cag. | B10: No permit/transport documents (Isuzu Elf with no Plate N0.) | C10: 111 ppcs. Red Lawan lumber | D10: =2356.66/424 -> 5.5581604 | F10: 58916.25 | G10: CENRO Aparri compound/Edgar T. Martin | H10: 26th CCAAC Patrol Base Company, Luga, Sta. Teresita, Cag. | I10: For reolution
A11: February 24, 2015/ Alagia, Lal-lo, Cagayan | B11: No claimant | C11: 75 pieces Gmelina lumber and 5 flitches | D11: =1041/424 -> 2.4551887 | F11: 27066 | G11: CENRO Aparri compound/Edgar T. Martin | H11: 17th IB Charlie Company, PA Alannay based at Lasam, Cagayan | I11: Under administrative adjudication proceedings
A12: February 26, 2015/ Catayauan, Lal-lo, Cag. | B12: No permit/transport documents (BVP-267) | C12: 13 pcs. Narra lumber | D12: =177.33/424 -> 0.41823113 | F12: 8866 | G12: CENRO Aparri compound/Edgar T. Martin | H12: PNP Lal-lo, Cagayan | I12: Confiscated in favor of the government datedFebruary 21, 2015. With Order of Finality received on Sept. 11, 2024
A13: March 3, 2015/ Macanaya, Aparri, Cagayan | B13: No permit/transport documents (BVP-264) | C13: 25 sacks charcoal | F13: 3750 | G13: CENRO Aparri compound/Edgar T. Martin | H13: Maritime Police Precint, Macanaya Wharf Aparri, Cag. | I13: Confiscated in favor of the government per order of the RED dated June 10, 2016. The Motion for Reconsideration is denied per order dated February 8, 2017. With Order of Finality received on Aug. 27, 2024
A14: March 13, 2015/ Dumasag, Rapuli, Sta. Ana, Cagayan | B14: No claimant | C14: 7 pcs. Red Lauan lumber | D14: =233/424 -> 0.5495283 | F14: 5825 | G14: Composite-Monitoring Center, Casambalangan, Sta. Ana, Cag. | H14: CEZA | I14: Under administrative adjudication proceedings
A15: April 5, 2015/ Ziminila, Camalaniugan, Cag. | B15: No claimant | C15: 7 sacks charcoal | F15: 2550 | G15: CENRO Aparri compound | I15: Confiscated in favor of the government per order of the RED dated June 10, 2015. With Order of Finality received on Dec. 09, 2024 promulgated on June 16, 2015 with Docket No. R2-F-1096
A16: April 23, 2015/ Abulug National Rural and Vocational High School, Langcay, Abulug, Cagayan | C16: 10 Narra flitches, 1 Office Table, & 4 Tool Cabinets | I16: With Order of Finality received on Dec. 03, 2024 promulgated on Aug. 12, 2015 with Docket No. R2-F-1101
A17: April 29, 2015/ San Vicente, Sta. Ana, Cagayan | B17: (Motorized Banca) | C17: 20 pcs. Red Lauan/ Narra lumber | D17: 0.34 | F17: 19588 | G17: Philippine Navy, NBCO/ Camilo Osias | H17: Philippine Navy, NBCO | I17: Under administrative adjudication proceedings
A18: May 1, 2015/ Bulala, Camalaniugan, Cagayan | B18: tricycle Kulong-kulong | C18: 60 pcs. Red Lauan lumber | D18: =328/424 -> 0.77358491 | F18: 8200 | G18: CENRO Aparri compound | I18: For reolution
A19: June 23, 2015/ Bulala, Camalaniugan, Cagayan | B19: Kulong-kulong w/ Plate No. BA-75835 | C19: 18 pcs. White Lauan lumber | D19: =118/424 -> 0.27830189 | F19: 3540 | G19: CENRO Aparri compound/Edgar T. Martin | I19: Confiscated in favor of the government per order of the RD dated May 12, 2016
A20: June 23, 2015/So. Salwang, Kapanikian, Sta. Ana, Cagayan | B20: No claimant | C20: 34 pcs. Apitong and Red Lauan lumber/flitches | D20: 2.57 | F20: 27301 | H20: LGU MENRO, Sta. Ana and PNP Sta. Ana | I20: Confiscated in favor of the government per order of the RD dated November 26, 2015. With Order of Finality received on Dec. 09, 2024 promulgated on Nov. 26, 2015 with Docket No. R2-F-1117
A21: June 24, 2015/ So. Salwang, Barangay Kapanikian, Sta. Ana, Cag. | B21: No claimant | C21: 19 pieces Red Lauan lumber | D21: 0.56 | F21: 6000 | H21: PNP Sta. Ana | I21: Confiscated in favor of the government per order of the RD dated November 26, 2015. With Order of Finality received on Dec. 09, 2024 promulgated on Nov. 26, 2015 with Docket No. R2-F-1116
A22: July 3, 2015/ Katiwayan, Rapuli, Sta. Ana, Cagayan | B22: No claimant | C22: 28 pcs. Red Lauan lumber/ flitches | D22: 1.49 | F22: 15814 | H22: PNP-RMG Casambalangan | I22: Confiscated in favor of the government per order of the RED dated August 12, 2015. With Order of Finality received on Dec. 03, 2024 promulgated on Aug. 12, 2015 with Docket No. R2-F-1099
A23: July 8, 2015/ Samuk-Samik, Centro, Sta. Ana, Cagayan | B23: No claimant | C23: 44 pieces Red Lauan lumber | D23: 1.32 | F23: 14049 | G23: MENRO Designate, Florence Obiano | H23: LGU MENRO and PNP Sta. Ana | I23: Confiscated in favor of the government per order of the RED dated August 19, 2015. With Order of Finality received on Dec. 03, 2024 promulgated on Aug. 19, 2015 with Docket No. R2-F-1109
A24: July 17, 2015/ Salwang, Kapanikian, Sta. Ana, Cagayan | B24: No claimant | C24: 37 pcs. Red Lauan | D24: 1.47 | F24: 15683 | G24: MENRO Designate, Florence Obiano | H24: LGU MENRO and PNP Sta. Ana | I24: Confiscated in favor of the government dated January 8, 2016. Ordered final and executory dated March 1, 2021
A25: July 27, 2015/ Salwang, Kapanikian, Sta. Ana, Cagayan | B25: No claimant | C25: 153 pcs. Red Lauan | D25: 9.14 | F25: 77546.2 | G25: MENRO Designate, Florence Obiano | H25: LGU MENRO and PNP Sta. Ana | I25: Confiscated in favor of the government dated January 12, 2016. Ordered final and executory dated March 1, 2021
A26: July 9, 2015/ Sta. Clara, Sta. Ana, Cagayan | B26: No permit to cut (Charlie Legaspi) | C26: 185 pcs. Narra and Red Lauan timber | D26: 26.85 | F26: 161100 | G26: MENRO Designate, Florence Obiano | H26: LGU MENRO and PNP Sta. Ana | I26: Under administrative adjudication proceedings
A27: July 9, 2015/ Sta. Clara, Sta. Ana, Cagayan | B27: No permit to cut (Ernesto Cadiz) | C27: 180 pcs. Red and White Lauan timber | D27: 44.87 | F27: 224350 | G27: MENRO Designate, Florence Obiano | H27: LGU MENRO and PNP Sta. Ana | I27: Under administrative adjudication proceedings
A28: July 28, 2015/ Camiguin, Calayan, Cagayan | B28: No claimant | C28: 5 pcs. Narra lumber | D28: 0.77 | F28: 19558.8 | G28: PCG District Office, Minanga, Aparri, Cag./ Lt. Senior Grade Edgardo Aguilar | H28: PCG District Office | I28: Confiscated in favor of the government dated February 4, 2016. Ordered final and executory dated March 15, 2021
A29: August 1, 2015/San Vicente, Sta. Ana, Cagayan | B29: Motorized Banca | C29: 32 pcs. White Lauan lumber | D29: 0.37 | F29: 3966.25 | G29: PN, NBCO, San Vicente, Sta. Ana, Cag./ Lt. Coomander Renato Ringor | H29: Philippine Navy | I29: Confiscated in favor of the government dated November 4, 2015
A30: August 3, 2015/ Pateng, Gonzaga, Cagayan | B30: PUV BVE-373 | C30: 22 pcs. Red Lauan lumber | D30: 0.75 | F30: 7957.75 | G30: CENRO Aparri compound/Edgar T. Martin | H30: LGU MENRO Gonzaga and PNP Gonzaga | I30: For resolution. With Order of Finality received on Aug. 27, 2024
A31: August 14, 2015/ San Vicente, Sta. Ana, Cagayan | B31: Motorized Banca | C31: 8 pcs. Gatasan lumber | D31: =208.33/424 -> 0.49134434 | F31: 5208.25 | G31: PN, NBCO, San Vicente, Sta. Ana, Cag./ Lt. Coomander Renato Ringor | H31: Philippine Navy | I31: For resolution
A32: Aug. 17, 2015/ San Vicente, Strait, Sta. Ana, Cag. | B32: No permit/transport documents (Motorized Banca) | C32: 44 pcs. Red Lauan lumber | D32: 0.57 | F32: 6116.5 | G32: PN, NBCO, San Vicente, Sta. Ana, Cag./ Lt. Coomander Renato Ringor | H32: Philippine Navy | I32: For resolution
A33: September 7, 2015/ Fusina, Lal-lo, Cagayan | B33: Handtractor/ Kuliglig | C33: 6 pcs. Narra lumber | D33: =75.99/424 -> 0.1792217 | F33: 3799.5 | G33: CENRO Aparri compound/Edgar T. Martin | H33: BLGU Fusina Lal-lo, Cag. | I33: For reolution
A34: September 7, 2015/ Fusina, Lal-lo, Cagayan | B34: Handtractor/ Kuliglig | C34: 6 pcs. Narra lumber | D34: =84.99/424 -> 0.20044811 | F34: 4249.5 | G34: CENRO Aparri compound/Edgar T. Martin | H34: BLGU Fusina Lal-lo, Cag. | I34: For reolution
A35: September 13, 2015/ Dungeg, Sta. Ana, Cagayan | B35: No claimant | C35: 50 pcs. Red Lauan lumber | D35: 0.9 | F35: 9545.75 | G35: MENRO Designate, Florence Obiano | H35: LGU MENRO and PNP Sta. Ana | I35: Under administrative adjudication proceedings
A36: September 15, 2015/ Dungeg, Sta. Ana, Cag. | B36: No claimant | C36: 23 pcs. Red Lauan lumber | D36: 1.18 | F36: 12525 | G36: MENRO Designate, Florence Obiano | H36: LGU MENRO and PNP Sta. Ana | I36: Confiscated in favor of the government dated January 8, 2016. Ordered final and executory dated March 1, 2021
A37: September 17, 2015/ Cumao, Gattaran, Cagayan | B37: No claimant | C37: 6 pcs. CHW flitches | D37: 1.03 | I37: Under administrative adjudication proceedings. Ewith Order of Finality received on Dec. 09, 2024 promulgated on Oct. 26, 2015 with Docket No. R2-F-114
A38: September 23, 2015/ Paranum, Lal-lo, Cagayan | B38: Handtractor/ Kuliglig | C38: 23 pcs. Narra lumber | D38: 0.24 | F38: 6234.6 | G38: CENRO Aparri compound/Edgar T. Martin | H38: PNP Lal-lo | I38: For resolution
A39: SUB-TOTAL | D39: =SUM(D8:D38) -> 106.60701 | F39: =SUM(F8:F38) -> 779177.79
A40: CENRO TUGUEGARAO
A41: February 3, 2015/ Dodan, Peñablanca, Cag. | B41: No claimant | C41: 48 pcs. CHW lumber | D41: =784/424 -> 1.8490566 | F41: 27440 | G41: PENRO, Sub-Office, Carig, Tuguegarao City | I41: Confiscated in favor of the government per order of the RED dated March 31, 2015. Ordered final and executory dated February 22, 2021
...

Sheet 2016
A1: CONSOLIDATED APPREHENDED, SEIZED AND CONFISCATED FOREST PRODUCTS, CONVEYANCES AND EQUIPMENT
A2: PROVINCE OF CAGAYAN
A3: CALENDAR YEAR 2016
A5: Date & Place of apprehension/ seizure & confiscation | B5: Circumstances of apprehension/ seizure & confiscation (e.g. no permit, or accompanying documents, etc.) | C5: Description of Forest Products | G5: Place Stockpiled and Custodian with complete address | H5: Other agencies involved in the apprehension/ seizure & confiscation (Names of personnel, LGUs, etc.) | I5: Other remarks (condition, status of criminal complaint if any, etc.)
C6: Quantity (# of pcs.) and form (lumber, logs, flitches, split/unsplit rattan, etc.) | D6: VOLUME (CU.M.) | E6: VOLUME (bd.ft.) | F6: Estimated Market Value (PhP)
A7: CENRO APARRI
A8: F ebruary 1, 2016/Guising, Gattaran, Cag. | B8: No permit to transport (UUL 360) | C8: 218 pcs. Red and White Lauan lumber | D8: 2.37 | F8: 25150 | G8: CENRO compound | H8: BLGU Guising Gattaran and PNP Gattaran | I8: Criminal case was filed in court against Nestor Pajudpud & Gerald Garcia docketed under NPS-II-02a-INV-16D-00099 on April 11, 2016. With Order of Finality received on sept. 11, 2024
A9: February 20, 2016/ Pateng, Gonzaga, Cagayan | B9: No permit to transport (020405) | C9: 11 kamagong lumber | D9: =109.5/424 -> 0.25825472 | F9: 5475 | G9: CENRO compound | H9: PNP Gonzaga | I9: The accused (Rodel Samortin) pleaded guilty for a lower offense 6 months to 2 years imprisonment and a fine of ₱500.00.The forest products and conveyance were ordered confiscated in favor of the government per order dated June 7, 2016 issued by Presiding Judge Conrado Tabaco of RTC Branch 9, Aparri, Cag. With Order of Finality received on Sept. 04, 2024
C10: 12 Narra lumber | D10: =146.49/424 -> 0.34549528 | F10: 7274.5
A11: February 20, 2016/ Brgy. Palawig, Sta. Ana, Cag. | B11: No permit to transport (BC-40918) | C11: 17 pcs. Red Lauan Lumber | D11: =204/424 -> 0.48113208 | F11: 5100 | G11: CENRO compound | H11: PNP Sta. Ana, Cagayan | I11: For resolution
A12: February 20, 2016/ Brgy. Centro, Sta. Ana, Cag. | B12: No permit to transport (Kulong-kulong) | C12: 13 pcs. Red Lauan Lumber | D12: =164/424 -> 0.38679245 | F12: 4100 | G12: CENRO compound | H12: PNP Sta. Ana, Cagayan | I12: For resolution
A13: February 20, 2016/ Brgy. Palawig, Sta. Ana, Cag. | B13: No permit to transport ( Center Car) | C13: 10 pcs. Red Lauan lumber | D13: =160/424 -> 0.37735849 | F13: 4000 | G13: CENRO compound | H13: PNP Sta. Ana, Cagayan | I13: For resolution
A14: March 10, 2016/ Centro West, Allacapan, Cagayan | B14: No permit to transport (TCC-198) | C14: 18 pcs. Gmelina lumbers | D14: =93/424 -> 0.21933962 | F14: 2418 | G14: CENRO compound | H14: PNP Allacapan | I14: Criminal Case was filed at OPP Ballesteros, Cag. Against Jaylord Salcedo on March 14, 2016. With Order of Finality received on Aug. 27, 2024
C15: 35 CHW lumber | D15: =358/424 -> 0.84433962 | F15: 10024 | G15: CENRO compound
A16: May 16, 2016/ Nangaramuan, Sta. Ana, Cag. | B16: Teddy Umbay | C16: 145 Red Lauan lumber | D16: =948.064/424 -> 2.236 | F16: 23712 | G16: Nangaramuan, San Vicente, Sta. Ana/Kagawad Eduardo Palor | I16: Criminal case was filed against Teddy Umbay at OPP Aparri on June 6, 2016 docketed under NPS-II-02a-INV-16F-00071
A17: June 15, 2016/ So. Lubac, San Vicente, Sta. Ana, Cag. | B17: No claimant | C17: 58 CHW lumber | D17: =610.56/424 -> 1.44 | F17: 12200 | G17: CENRO compound | I17: Confiscated in favor of the government dated November 2, 2017
A18: June 25, 2016/ Bukig, Aparri, Cagayan | B18: No permit to transport (RGY-413) | C18: 211 pcs. Red & White Lauan lumber | D18: 3.95 | F18: 50349 | G18: CENRO compound | H18: PNP Bangag, Aparri | I18: Criminal Case was filed against the 5 suspects Reynaldo Ramos, et.al. at PPO Aparri, Cag. On June 26, 2016 under Criminal Case No. II-13254
A19: June 29, 2016/ Lubac, San Vicente, Sta. Ana, Cag. | B19: No claimant | C19: 40 White Lauan lumber | D19: =387.34/424 -> 0.91353774 | F19: 9683.5 | G19: CENRO compound | H19: PNP Maritime Sta. Ana | I19: Confiscated in favor of the government dated October 27, 2017. Odered final and executory dated November 9, 2020
A20: July 5, 2016/Magapit, Lal-lo, Cag. | B20: No claimant | C20: 38 White Lauan lumber | D20: =537.93/424 -> 1.2687028 | F20: 13448.25 | G20: CENRO compound | H20: MENRO LAL-LO | I20: Under administrative adjudication proceedings
A21: July 6, 2016/ So. Salwang, Kapanikian, Sta. Ana, Cag. | B21: No claimant | C21: 18 Red Lauan lumber | D21: =300/424 -> 0.70754717 | F21: 7522 | G21: CENRO compound | I21: Confiscated in favor of the government dated September 24, 2017. Odered final and executory dated October 21, 2020
A22: July 10, 2016/ Centro East, Allacapan, Cag. | B22: No permit to transport (owner type jeep W/ Plate No. BCJ-516) unregistered/ Berting Gelano | C22: 6 Narra flitches | D22: =236.88/424 -> 0.55867925 | F22: 9475.2 | G22: CENRO compound | I22: Criminal case was filed against Berting Galano at RTC Ballesteros, Cag. Filed by PNP Allacapan. Confiscated in favor of the government dated October 15, 2020. Ordered final and executory dated April 12, 2022
A23: July 12, 2016/ Mammit, San Mariano, Lal-lo, Cag. | B23: No claimant (1 unit STIHL-Chainsaw | C23: 59 CHW lumber | D23: =643.45/424 -> 1.5175708 | F23: 16086.25 | G23: CENRO compound | H23: PNP Lal-lo | I23: Ordered final and executory dated Dec. 2020
A24: July 12, 2016/Palawig, Sta. Ana, Cag. | B24: No permit to transport (TMX 155) / Nestor Batacan, Joel Miranda & Toniline Alog | C24: 26 Red Lauan lumber | D24: =290/424 -> 0.68396226 | F24: 7250 | G24: CENRO compound | I24: Criminal Case filed against Nestor Batacan et.al. at PPO Aparri docketed under NPS No. II-02a-INQ-16G-00129 and Crim. Case No. 13273
A25: July 13, 2016/ Sta. Clara, Sta. Ana, Cag. | B25: No claimant | C25: 20 Red Lauan & Tuai lumber | D25: =1456.4/424 -> 3.4349057 | F25: 36410 | G25: CENRO compound | H25: PNP Sta. Ana, Cagayan | I25: Confiscated in favor of the government dated November 2, 2017. Ordered final and executory dated October 26, 2020
A26: September 3, 2016/ Visitacion, Sta. Ana, Cagayan | B26: Lani Laud Villacillo | C26: 57 Narra & CHW lumber & semi-finished products | D26: =377.5/424 -> 0.89033019 | F26: =19400+2855+3465 -> 25720 | G26: CENRO compound | I26: Apprehended through Search Warrant issued by Hon. Judge Canrado Tabaco on Sept. 2, 2016. A criminal case was filed against Lannie Villacillo under NPS No. II-02a-INV-16I-00278
A27: September 3, 2016/ Visitacion, Sta. Ana, Cagayan | B27: Lani Laud Villacillo | C27: 199 pcs. Premium and CHW lumber and semi-finished furniture items | D27: =1619.7/424 -> 3.8200472 | F27: =3840+38572.5 -> 42412.5 | G27: CENRO compound | H27: Barangay Officials, PNP Sta. Ana and Maritime Group | I27: Apprehended through Search Warrant issued by Hon. Judge Canrado Tabaco on Sept. 2, 2016. A criminal case was filed against Lannie Villacillo under NPS No. II-02a-INV-16I-00279
A28: October 7, 2016/ Marede, Sta. Ana, Cag. | B28: Marvin Agcaoili | C28: 46 Narra & Kamagong lumber/flitches | D28: =(64.16+1940.97)/424 -> 4.7290802 | F28: =3208+97048.5 -> 100256.5 | G28: CENRO compound | H28: PNP based at Casambalangan, Sta. Ana, Cag. | I28: The seizure was executed through Search Warrant No. 73-16 issued by Judge Neljoe A. Cortes RTC, Branch VI, Aparri, Cag. On Oct. 7, 2016. A criminal case was filed under NPS No. II-02a-INV-16K-00345. Confiscated in favor of the government per order dated October 31, 2019 issued by Atty. Antonio A. Abawag.Order of Finality date received January 8, 2025 and date promulgated October 31, 2019 and docket no. R2-F-1382
A29: October 15, 2016/ Centro Sta. Ana, Cag. | B29: No permit to transport (kulong-kulong) | C29: 15 CHW lumber | D29: =228/424 -> 0.53773585 | F29: 5700 | G29: CENRO compound | I29: For resolution
A30: October 15, 2016/Palawig, Sta. Ana, Cag. | B30: No permit to transport (kulong-kulong)/Jay-ar Burguita &Jay-mar Burguita | C30: 10 CHW lumber | D30: =96/424 -> 0.22641509 | F30: 2400 | G30: CENRO compound | I30: For resolution
A31: November 5, 2016/ Bulala Sur, Aparri, Cag. | B31: No permit/1 table saw/ Marlon Labbao | C31: 11 CHW lumber | D31: =226.03/424 -> 0.53308962 | F31: 4520 | G31: CENRO compound | H31: PNP Aparri | I31: The forest products and the undergeistered table saw were apprehended at the house and its premises of Marlon Labbao
A32: December 4, 2016/Palawig, Sta. Ana, cag. | B32: No permit to transport (kulong-kulong)/Gerald Malavi | C32: 9 CHW lumber | D32: =196/424 -> 0.46226415 | F32: 4900 | G32: CENRO compound | H32: PNP Sta. Ana, Cagayan | I32: For resolution
A33: December 4, 2016/Palawig, Sta. Ana, cag. | B33: No permit to transport (kulong-kulong)/Arnel Alog | C33: 7 CHW lumber | D33: =122.8/424 -> 0.28962264 | F33: 3070 | G33: CENRO compound | H33: PNP Sta. Ana, Cagayan | I33: For resolution
A34: SUB-TOTAL | D34: =SUM(D8:D33) -> 33.482203 | F34: =SUM(F8:F33) -> 438656.7
A35: CENRO TUGUEGARAO
A36: February 16, 2016/ Barangay Dadda, Tuguegarao City | B36: No permit to transport (Kuliglig) | C36: 25 pcs. CHW lumber | D36: =400/424 -> 0.94339623 | F36: 14000 | G36: PENRO Sub-Office | I36: Under administrative adjudication proceedings
A37: February 21, 2016/ San Gabriel, Tuguegarao City | B37: Abandoned | C37: 51 pcs. CHW lumber | D37: =731/424 -> 1.7240566 | F37: 25596.2 | G37: PENRO Sub-Office | I37: Confiscated in favor of the government dated June 9, 2016. oRDER FINAL AND EXECUTORY DATED mARCH 1, 2021
A38: March 3, 2016/ San Gabriel, Tuguegarao City | B38: No permit to transport (XGU 597) | C38: 26 pcs. Narra lumber | D38: =385/424 -> 0.90801887 | F38: 26950 | G38: PENRO Sub-Office | H38: PNP Tuguegarao | I38: Under administrative adjudication proceedings
A39: June 4, 2016/ Mayon St. San Gabriel, Tuguegarao City | B39: No permit to transport (RAA-957) | C39: 110 pcs. Gmelina lumber | D39: 2.362 | F39: 34047.6 | G39: PNP Compound | H39: PNP Tuguegarao | I39: Per memo dated November 15, 2016 of Legal Division, instructing the realese of both conveyance and its load
A40: August 6, 2016/ Nanguillattan, Peñablanca, Cag. | B40: abandoned | C40: 31 pcs. CHW flitches | D40: =1663/424 -> 3.9221698 | F40: 58205 | G40: PENRO Sub-Office | H40: PNP Tuguegarao | I40: Under administrative adjudication proceedings
A41: August 21, 2016/ Camasi, Peñablanca, Cagayan | B41: abandoned | C41: 25 CHW lumber | D41: 1.24 | F41: 18410 | G41: PENRO Sub-Office | I41: Confiscated in favor of the government dated November 10, 2016
...

Sheet 2017
A1: CONSOLIDATED APPREHENDED, SEIZED AND CONFISCATED FOREST PRODUCTS
A2: PROVINCE OF CAGAYAN
A3: CALENDAR YEAR 2017
A5: Date & Place of apprehension/ seizure & confiscation | B5: Circumstances of apprehension/ seizure & confiscation (e.g. no permit, or accompanying documents, etc.) | C5: Description of Forest Products | G5: Place Stockpiled and Custodian with complete address | H5: Other agencies involved in the apprehension/ seizure & confiscation (Names of personnel, LGUs, etc.) | I5: Other remarks (condition, status of criminal complaint if any, etc.)
C6: Quantity (# of pcs.) and form (lumber, logs, flitches, split/unsplit rattan, etc.) | D6: VOLUME (CU.M.) | E6: VOLUME (bd.ft.) | F6: Estimated Market Value (PhP)
A7: CENRO APARRI
A8: February 4, 2017/ San Vicente Port, San Vicente, Sta. Ana, Cag. | B8: Marlon Pailano | C8: 20 pcs. Bantigue (Bonsai) | H8: NBCO San Vicente, Sta. Ana/CDR Renato T. Ringor, PN | I8: No detailed report submitted yet
A9: February 14, 2017 /So. Bigok, Alucao, Sta. Teresita, cag. | B9: No claimant | C9: 80 pcs. Red and White Lauan lumber/ flitches | D9: 4.38 | F9: 1856.79 | G9: PNP Station | H9: PNP Sta. teresita | I9: The report was received by this office on July 28, 2017
A10: February 17, 2017/ So. Bigok, Alucao, Sta. Teresita, Cag. | B10: No claimant | C10: 14 pieces CHW lumbers/fltiches | D10: =1391.76/424 -> 3.2824528 | F10: 34793.25 | G10: CENRO compound | I10: Under administrative confiscation proceedings
A11: February 21, 2017/ So. Palabirit, Barangay Dungeg, Sta. Teresita, Cagayan | B11: No claimant | C11: 2 pcs. Narra flitches | D11: =106.75/424 -> 0.25176887 | F11: 17933 | G11: CENRO compound | H11: Bravo Company, 17th IB, 5ID, PA based at Sta. Teresita, Cag. | I11: Under administrative adjudication proceedings
C12: 6 pcs. CHW lumber/flitches | D12: =503.82/424 -> 1.1882547
A13: February 23, 2017/Mabuno, Gattaran, Cagayan | B13: No permit to transport (BVD-794) | C13: 89 pcs. CHW lumber | D13: =487.6/424 -> 1.15 | F13: 14628 | G13: CENRO compound | H13: PNP Gattaran, Cag. | I13: Criminal Case filed against the 4 apprehended persons docketed under NPS II-02a-INV-17C-00073. With Order of Finality received on Sept. 04, 2024
A14: February 26, 2017/Pina Este, Gattaran Cag. | B14: No claimant | C14: 20 pieces Gmelina lumbers | D14: =712.75/424 -> 1.6810142 | F14: 13829.5 | G14: CENRO compound | I14: Under administrative confiscation proceedings
A15: February 27, 2017/Punta, Aparri, Cag. | B15: No permit to transport (motorized banca) | C15: 117 pieces White Lauan lumbers | D15: =312.9/424 -> 0.7379717 | F15: 7822.5 | H15: Brgy. Punta, Aparri | I15: Apprehended persons are Melvin Quillapo-operator, Nelia Basilio-owner of boat; owner of lumber are Arsenio Rabina, Herman Quillapo and Junior Rabina. The apprehended boat was brought Punta, Aparri, Cag.
A16: February 27, 2017/Punta, Aparri, Cag. | B16: No claimant | C16: 24 pieces CHW lumbers | D16: =121.7/424 -> 0.2870283 | F16: 3651 | G16: CENRO compound | I16: Under administrative confiscation proceedings
A17: February 28, 2017/Sta. Clara, Gonzaga, Cag. | B17: No claimant | C17: CHW lumbers | D17: =360/424 -> 0.8490566 | I17: Under administrative confiscation proceedings
A18: March 9, 2017/ Bulala, Camalaniugan, Cag. | B18: Public Utility Vehicle Multicab BCK 997 | C18: 30 sacks charcoal | F18: 3000 | G18: CENRO compound | I18: Registered owner is Mr. Redencio E. Manio of Rizal St., Aparri, Cag., Simon I. Gomer - driver, Vilma Gomer-helper of Toran, Aparri, Cag.
A19: March 9, 2017/ Sta. Maria, Lal-lo, Cagayan | B19: Honda TMX w/ sidecar 4274-VM) | C19: 70 bundles firewood | F19: 490 | G19: CENRO compound | I19: The driver and the owner Mr. Melvin Gonzales
A20: March 9, 2017/ Mangaoan Point, Palaui Island, San Vicente, Sta. Ana, Cag. | B20: (1 chainsaw w/ serial No. 505141042) | H20: NBCO San Vicente, Sta. Ana/CDR Renato T. Ringor, PN | I20: A case was filed in court against Jose Aquiliano Cabingan
A21: March 10, 2017/ Bulala, Camalaniugan, Cag. | B21: No permit to transport (PUJ w/ Plate No. CKH 985) | C21: 50 sacks charcoal | F21: 5000 | G21: CENRO compound | I21: Rodolfo Valdez - driver, Rowena Rosario - owner
C22: 16 pcs. White Lauan lumber | D22: =64/424 -> 0.1509434 | F22: 1920
A23: March 10, 2017/ Joaquin dela Cruz, Camalaniugan, Cag. | B23: No permit to transport (Motorized banca) | C23: 29 pcs. Poles of CHW lumbers | D23: 0.44 | F23: 3694.8 | G23: CENRO compound | I23: Arthur Manuel-owner of the boat, Arvin Manuel
A24: March 10, 2017/ Minanga, Aparri, cag. | B24: No permit to transport (Kulong-kulong w/ Plate No. 6364 BW) | C24: 14 sacks charcoal | F24: 1400 | G24: CENRO compound | I24: Benjamin A. Delodado - driver
A25: March 10, 2017/ Bulala, Camalaniugan, Cag. | B25: No permit to transport (handtractor) D1800 | C25: 120 bundles firewood | F25: 14400 | G25: CENRO compound | I25: Confiscated in favor of the government dated September 2, 2020. Orderedf final and executory dated November 15, 2021
A26: March 12, 2017/ So. Dumasag, Sta. Ana, Cag. | B26: STHIL Chainsaw w/ SN 303061983 | G26: CENRO compound | I26: A case was filed in court against Rommel Inay
A27: March 12, 2017/Lubac, San Vicente, Sta. Ana, Cag. | B27: No claimant | C27: 53 pcs. CHW lumber | D27: =209.45/424 -> 0.49398585 | F27: 8857.25 | G27: CENRO compound | I27: Under administrative confiscation proceedings
C28: 14 pcs. Gmelina lumber | D28: =144.16/424 -> 0.34
A29: March 12, 2017/ So. Limbus, Rapuli, Sta. Aca, Cag. | B29: No claimant | C29: 169 pcs. White and Red Lauan lumber | D29: =1231/424 -> 2.9033019 | F29: 30825 | G29: CENRO compound | I29: Under administrative confiscation proceedings
A30: March 13, 2017/ Sta. Clara, Gonzaga, Cag. | B30: No claimant | C30: 26 pcs. Red Lauan, White Lauan and Barosingsing | D30: =712.67/424 -> 1.6808255 | F30: 17307 | G30: CENRO compound | I30: Under administrative confiscation proceedings
A31: March 13, 2017/ Sta. Cruz, Gonzaga, Cag. | B31: No claimant | C31: 8 pcs. Narra lumbers | D31: 0.73 | F31: 21700 | G31: PNP Head Quarter Gonzaga, Cag. PSI Edgar Manuel, Jr. | I31: Under administrative confiscation proceedings
A32: March 14, 2017/ Joaquin dela Cruz | B32: No claimant | C32: 4 pcs. CHW posts | D32: =394.32/424 -> 0.93 | F32: 5914.8 | G32: CENRO compound | I32: Under administrative confiscation proceedings
C33: 4 pcs. Tangising Bayawak | D33: =487.6/424 -> 1.15 | F33: 5851.2
A34: March 14, 2017/Rapuli, Sta. Ana, Cag. | B34: Kulong-KulongHatwa PMR150cc | C34: 15 pcs. White Lauan lumber | D34: 0.393 | F34: 4166.25 | G34: Barangay Captain Tito Candillario | I34: For resolution
A35: March 15, 2017/ Sta. Clara, Sta. Ana, Cagayan | B35: (Motorcycle Rusi motor w/o Plate No.) | C35: 6 pcs. Narra lumbers | D35: =28.7/424 -> 0.067688679 | F35: 2009 | G35: CENRO compound | I35: The driver and the owner of the f.p was identified as Franco Ladera of Patunungan, Sta. Ana, Cag. Criminal complaint was filed at Fiscals Office, Aparri, Cagayan
A36: March 15, 2017/ Dungeg, Sta. Ana, Cagayan | B36: Rusi motor w/o Plate No.) | C36: 29 pcs. CHW lumber | D36: =557/424 -> 1.3136792 | F36: 16710 | G36: CENRO compound | I36: Diosdado Barbara-driver. Criminal complaint was filed at Fiscals Office, Aparri, Cagayan
A37: March 16, 2017/ Sta. Clara, Sta. Ana, cag. | B37: Kulong-kulong no plate | C37: 14 pcs. Narra lumber | D37: =163/424 -> 0.38443396 | F37: 11445 | G37: CENRO compound | I37: The driver not yet identified
A38: March 16, 2017/ Sta. Clara, Sta. Ana, cag. | C38: 49 pcs. CHW, Narra & Kamagong lumber/flitches | D38: =950.48/424 -> 2.2416981 | F38: 44611.4 | G38: CENRO compound | H38: PNP Sta. Ana | I38: Under administrative adjudication proceedings
A39: March 18, 2017/ Macanaya, Aparri, Cag. | B39: van MB100D no plate | C39: 20 sacks charcoal | F39: 2000 | G39: CENRO compound | I39: With resolution received on 'July 24, 2024 promulgated on 'July 09, 2024 with Docket Number R2-ED-2024-0035 respondents Mr. Fernando Juan & Mr. Antonio Taloza
A40: March 19, 2017/ Dugo, Camalaniugan, Cag. | B40: Center Car Yamaha RS 110F Black with plate no. BC-25062 | C40: 49 bundles firewood | G40: CENRO compound | I40: The admin. Proceedings was conducted last March 30 and April 28, 2017. With Order of Finality received on Sept. 06, 2024.
A41: March 19, 2017/ Tucalana, Lal-lo, Cag. | B41: Euro 150cc tricy no Plate | C41: 8 sacks charcoal | F41: 800 | G41: CENRO compound | I41: For resolution
...

Sheet 2018
A1: CONSOLIDATED APPREHENDED, SEIZED AND CONFISCATED FOREST PRODUCTS
A2: PROVINCE OF CAGAYAN
A3: CALENDAR YEAR 2018
A4: Date & Place of apprehension/ seizure & confiscation | B4: Circumstances of apprehension/ seizure & confiscation (e.g. no permit, or accompanying documents, etc.) | C4: Description of Forest Products | G4: Place Stockpiled and Custodian with complete address | H4: Other agencies involved in the apprehension/ seizure & confiscation (Names of personnel, LGUs, etc.) | I4: Other remarks (condition, status of criminal complaint if any, etc.)
C5: Quantity (# of pcs.) and form (lumber, logs, flitches, split/unsplit rattan, etc.) | D5: VOLUME (CU.M.) | E5: VOLUME (bd.ft.) | F5: Estimated Market Value (PhP)
A6: CENRO APARRI
A7: January 9, 2018/ So. Nangaramoan, San Vicente, Sta. Ana, Cag. | B7: No permit (Jojo Fabro) | C7: 36 pcs. Palosapis and Red Lauan lumber | D7: 0.91 | F7: 9597.5 | G7: CENRO Compound | I7: Under admin. Confiscation proceedings
A8: January 17, 2018/ San Mariano, Lal-lo, Cag. | B8: No claimant | C8: 10 pcs. Palosapis and Red Lauan lumber | D8: 0.17 | F8: 1800 | G8: CENRO Compound | I8: Under admin. Confiscation proceedings
A9: January 19, 2018/ So. Limbus, Rapuli, Sta. Ana, Cag. | B9: Kulong-kulong no plate | C9: 8 pcs. White and Red Lauan lumbers | D9: 0.36 | F9: 3825 | G9: CENRO Compound | I9: For resolution
A10: January 21, 2018/Smart, Gonzaga, Cag. | B10: Isuzu Elf Van w/ temporary Plate No. 138005) | C10: 46 pcs. Narra flitches and Kamagong lumbers and 1 kamagong sala set | D10: 2.72 | F10: 42995.2 | G10: CENRO Compound | H10: PNP Gonzaga and Barangay Officials of Smart, Gonzaga, Cag. | I10: The admin proceedings was conducted last February 13 & 15, 2018. A crminal Case was filed on February 6, 2018 at PPO Aparri, Cag docketed under NPS-II-02a-INV-18A-00030. The forest products was ordered confiscated in favor of the government while the conveyance was ordered release per order dated October 29, 2018
A11: January 22, 2018/ within the cmpd of Pattao Elementary School, Pattao, Buguey, cag. | B11: No permit | C11: 17 pcs. Red Lauan lumber | D11: 0.16 | F11: 1700 | G11: LGU Buguey/MENRO May Jocelyn Joan S. Lee | H11: MENRO Buguey | I11: Case was filed against Arnel Andres & Ariston Molina for violation of PD 705 at the PPO Aparri on Jan. 29, 2018 under NPS Docket No. II-02a-INV-18A-0002
A12: January 25, 2018/ So. Cruzadan, San Mariano, Lal-lo, Cag. | B12: No claimant | C12: 13 pcs. Red Lauan flitches | D12: 1.7 | F12: 18000 | G12: CENRO Compound | H12: Phil. Army | I12: Under admin. Confiscation proceedings
A13: January 27, 2018/ Dungeg, Sta. Teresita, Cag. | B13: No permit to transport 1 unit table saw w/ engine WD 11-diesel-engine) | C13: 25 pcs. Red Lauan lumber, and 9 pcs. Red Lauan flitches | D13: 2.9 | F13: =4440+21068 -> 25508 | G13: CENRO Compound | I13: The identified owner of the f.p are Narding Tactac and Romnic Ocampo while the owner of the table saw is Dante Bañez. Under admin confiscation proceedings
A14: January 31, 2018/Diora-Zinungan, Sta. Ana, Cagayan | B14: No claimant | C14: 1 pc. Narra table top | D14: 0.12 | F14: 2626 | G14: CENRO Compound | I14: Under admin. Confiscation proceedings
A15: February 5, 2018/ Capissayan Sur, Gattaran, Cag. | B15: No claimant | C15: 8 pcs. Gmelina flitches | D15: 1.19 | F15: 12562.5 | G15: CENRO Compound | I15: 7 pcs. With a volume of 436.5 bd.ft. were donated to Camalaniugan National High School
A16: February 14, 2018/Bagsang, Sta. Clara, Gonzaga, Cag. | B16: No permit (1 unit chainsaw) | G16: CENRO Compound | I16: The owner is Ruben Gamboa
A17: February 17, 2018/ Guiddam, Abulug, Cag. | B17: Isuzu Forward TKF-963) | C17: 203 pcs. CHW lumbers | D17: 9.99 | G17: CENRO Compound | H17: PNP-CIDG, RO2 | I17: A criminal complaint was filed by CIDG at the DOJ PPO, Ballesteros, Cagayan docketed under NPS No. II-02B-INQ-018B-005. The admin proceeding was conducted last February 27, 2018. The accussed Bennie Torres, Frendy Marina, Noel Torres, Marlon Rivera, and Marino Ursua were sentenced to 4 months and 1 day or aresto mayor as minimum to 2 years, 4 months and 1 day prison correctional as maximum and the confiscated items were ordered forfeited per DECISSION dated May 8, 2018 issued by Executive Judge Francisco Donato, RTC Branch 33, Ballesteros, Cag. The 87 pcs. Red Lauan lumber with a volume of 1,983.4 bd.ft. were transferred to PENRO Cagayan thru PENRO rep. Vicente Tuliao on June 8, 2018. With Order of Finality received on Sept. 06, 2024. | J17: Promulgated on April 17, 2024 with Docket No. R2-ED-2024-00117 received on June 20, 2024
A18: February 17, 2018/ Sirrit, Abulug, Cag. | B18: No permit to transport (Isuzu Dump Trucl w/ Plate No. WKN-571) | C18: 133 pcs. CHW lumbers | D18: =3760.47/424 -> 8.869033 | F18: 112814 | G18: CENRO Aparri Compound | H18: PNP-CIDG | I18: A criminal case was filed against the offenders on Feb. 19, 2018 at PPO Ballesteros, Cag docketed under NPS II-02B-INQ-018B-004. The admin proceeding was conducted last February 27, 2018. The accused Jefrey Andres, Roderick Aurina & Jr. C. Carpo was sentenced to 4 months and 1 day or aresto mayor as minimum to 2 years, 4 months and 1 day prison correctional as maximum and the confiscated items were ordered forfeited per DECISSION dated May 8, 2018 issued by Executive Judge Francisco Donato, RTC Branch 33, Ballesteros, Cag. The volume of 3,760.47 bd.ft. was approved for utilization of CENRO concerned by the then RED Aromin. With Order of Finality received on Sept. 06, 2024.
A19: March 8, 2018/ Turkia, Gonzaga, cag. | B19: (Eur motorcycle w/ sidecar) | C19: 14 pcs. White Lauan lumbers | D19: =168/424 -> 0.39622642 | F19: 5040 | G19: CENRO Aparri Compound | H19: PNP-CIDG | I19: A case was filed against PNP CIDG Aparri against Justino Espiritu at PPO Aparri on March 8, 2018 under NPS Docket No. II-02a-INQ-18C-00024
A20: March 10, 2018/Golden Valley, San Mariano, Lal-lo, Cag. | B20: No permit (Noel Tiansan & Imelda Gamilla | C20: 256 pcs. Poles/posts | D20: =4324.8/424 -> 10.2 | F20: 3060 | G20: CENRO Aparri Compound | I20: Under admin. Confiscation proceedings
A21: March 12, 2018/ Sta. Clara, Sta. Ana, Cag. | B21: No claimant | C21: 5 pcs. Kamagong | D21: =176/424 -> 0.41509434 | F21: 8800 | G21: CENRO Aparri Compound | I21: Under admin. Confiscation proceedings
C22: 22 pcs. Narra flitches | D22: =742.6/424 -> 1.7514151 | F22: 37130 | G22: CENRO Aparri Compound
C23: 12 pcs. Red Lauan lumber | D23: =206/424 -> 0.48584906 | F23: 5100 | G23: CENRO Aparri Compound
A24: March 16, 2018/Nabaccayan, Gattaran, Cag. | B24: Isuzu Elf WJB-407 | C24: 282 pcs. Dao, Mayapis, Red Lauan and Narra lumber | D24: =2614.3/424 -> 6.1658019 | F24: 67467.5 | G24: CENRO Aparri Compound | H24: PNP Gattaran | I24: A case was filed by PNP Gattaran against Roy Bitanga and Rowel Bagaoisan at PPO aparri on March 17, 2018 under NPS Docket No. II-02a-INQ-18C-00027
A25: March 19, 2018/ Pateng Gonzaga, cag. | B25: Honda TMX 155 kulong-kulong no plate | C25: 1 pcs. Tanguile & 6 pcs. Narra lumber | D25: =74.73/424 -> 0.17625 | F25: 2899.2 | G25: CENRO Aparri Compound | I25: The driver was not identified since he was escaped during the operation
A26: March 22, 2018/ Tallungan, Aparri, Cag. | B26: (kuliglig w/ trailer) | C26: 30 pcs. Red Lauan lumber | D26: =122.64/424 -> 0.28924528 | F26: 3679.2 | G26: Brgy. Tallungan, Parri under the custody of Barangay Captain | I26: The identified driver and owner of the kuliglig is Bo Delelis, and the helper is Jobert Alariao
A27: March 23, 2018/ Cabatacan West, Lasam, Cag. | B27: No claimant | C27: 28 pcs. Miscellaneous lumber | D27: =327.75/424 -> 0.77299528 | F27: 6555 | G27: Brgy. Hall, Cabatacan West, Lasam, cag./ Brgy. Captain Xerxes Almazan | I27: Under admin proceedings
A28: March 23, 2018/ Centro Buguey, Cagayan | B28: Hand Tractor, color red | C28: 162 pcs. CHW lumbers | D28: =302.94/424 -> 0.71448113 | F28: 8179 | G28: CENRO Aparri Compound | H28: PNP Buguey | I28: A criminal case was filed by PNP Buguey at PPO Aparri docketed under NPS No. II-02a-INQ-00029. Confiscated in favor of the government dated Dec. 14, 2018. With Order of Finality received on Sept. 16, 2024
A29: March 28, 2018/ Gonzaga, Cagayan | B29: No permit to transport (1 kulong-kulong) | G29: CENRO Aparri Compound | I29: Confiscated in favor of the government dated December 14, 2018
A30: March 30, 2018/ | B30: Ford Fiera Type Jeepney no plate and 1 chainsaw) | C30: 3 chairs, 6 seaters dining set | G30: CENRO Aparri Compound | I30: For resolution
A31: April 17, 2018/ Sta. Clara, Sta. Ana, Cag. | B31: No claimant | C31: 10 pcs. Narra flitches | D31: =465.7/424 -> 1.0983491 | F31: 23285 | G31: Naval Base Camilo Osias, San Vicente, Sta. Ana, Cag. | H31: Phil Navy | I31: Under admin. Adjudication proceedings
C32: 1 pc. Narra lumber | D32: =9.3/424 -> 0.021933962 | F32: 558
C33: 25 pcs. CHW lumber | D33: =320.01/424 -> 0.75474057 | F33: 9627
A34: May 8, 2018/ Diora Zinungan, Sta. Ana, Cagayan | B34: chainsaw | I34: The identified owner is Mario Targat. Under admin confiscation proceedings
A35: May 12, 2018/ Gaddang, Aparri, Cagayan | B35: Isuzu Aluminum Van WTA 870) | C35: 25 pcs. Assorted sizes white Lauan lumbers | D35: =203/424 -> 0.47877358 | F35: 6090 | G35: CENRO Aparri Compound | H35: PNP-CIDG | I35: The admin proceeding was conducted last July 11, 2018. A criminal case was filed against Bonifacio Calandoy (lumber owenr) and Jerwin Marinmin (driver) at PPO Aparri, Cagayan docketed under NPS-II-02a-INQ-18E-00065. The accussed pleaded guilty for alower offense & were sentenced to suffer an imprisonment from 2 months as minimum to 2 years and 4 months as 1,000.00 each. And, the apprehended contraband was ordered forfeited in favor of the government per Order dated May 23, 2018 issued by Presiding Judge Conrado Tabaco, RTC Branch 9, Aparri, Cag. Confiscated in favor of the government dated August 29, 2019
A36: May 14, 2018/ So. Dakkel Danum, Minabel, Camiguin Island, Cag. | B36: No permit | C36: 1 pcsc. Narra lflitches | D36: =76/424 -> 0.17924528 | F36: 50000 | G36: CENRO Aparri Compound | H36: PNP Maritime Group, Regional Maritime Unit based at Minanga, Aparri, Cag. | I36: A case was filed at Ppo Aparri, Cag. By the PNP Maritime Group against the accused Pedrito Peralta on May 17, 2018 under NPS Docket No. II-02a-INV-18E-00121
A37: May 15, 2018/Bicud, Lal-lo, Cag. | B37: Nissan Caravan Van BDA-521) | C37: 19 pcs. Narra lumber | D37: =227.28/424 -> 0.53603774 | F37: 13636 | G37: CENRO Aparri Compound | H37: PNP Lal-lo | I37: A case was filed against Rey Virgilio Bagoyo, Rolly Cabael and David Cabael, Sr. on May 16, 2018 at PPO Aparri under NPS Docket No. II-02a-INQ-18E-0016. The accussed Rey Virgilio Bagoyo and Rolly Cabael guilty beyond reasonable doubt for violation of Section 78 of PD 705 and the forest products and the conveyance were confiscated in favor of the government per Order dated May 23, 2018 issued by Judge Conrado Tabaco, RTC Branch 9, Aparri, Cag.
A38: May 23, 2018/ Paruddun Norte, Aparri, Cag. | B38: uro kulong-kulongno plate | C38: 22 pcs. Rimas lumber | D38: =96.3/424 -> 0.22712264 | F38: 2407 | G38: CENRO Aparri Compound | H38: PNP Aparri | I38: A case was filed against Richard Areola and Jaymar Pablo for violation of PZD 705 at PPO Aparri on May 23, 2018 docketed under Criminal Case No. II-14201. Turned-over to CENRO on May 23, 2018
A39: May 23, 2018/ Paruddun Norte, Aparri, Cagayan | B39: Honda TMX 155 kulong-kulong no plate | C39: 22 pcs. Lumber | D39: =102.6/424 -> 0.24198113 | F39: 2565 | G39: CENRO Aparri Compound | H39: PNP Aparri | I39: A case was filed by PNP Aparri Police Station against the accussed Bonifacio Areola and John Doe for violation of PD 705 at PPO Aparri on May 23, 2018 docketed under Criminal Cae No. II-14202. Truned-over to CENRO ON May 23, 2018
A40: May 24, 2018/ Peru, Lasam, Cag. | B40: No claimant | C40: 4 pcs. Gmelina flitches | D40: 1.027 | F40: 10888.75 | G40: CENRO Aparri Compound | H40: 17th IB, Philippine Army | I40: Under administrative confiscation proceedings
...

Sheet 2019
A1: CONSOLIDATED APPREHENDED, SEIZED AND CONFISCATED FOREST PRODUCTS, CONVEYANCES AND TOOLS/EQUIPMENT
A2: PROVINCE OF CAGAYAN
A3: CALENDAR YEAR 2019
A5: Date OF Apprehension | B5: Place of Apprehension | C5: Apprehending Officers | D5: Forest Products | G5: Conveyance/Equipment | H5: Place Impouded | I5: Other remarks (condition, status of criminal complaint if any, etc.)
D6: Quantityand form | E6: Volume (cu.m.) | F6: Value (PhP)
A7: CENRO APARRI
A8: January 9, 2019 | B8: So. Bigok, Alucao, Sta. Teresita, Cagayan | C8: Phil. Marines based at St Mission, Sta. Teresita, Cagayan | D8: 7 pcs. Red Lauan flitches | E8: 2.61 | F8: 33300 | H8: CENRO Compound | I8: Under administrative confiscation proceedings
A9: January 22, 2019 | B9: Capissayan Sur, Gattaran, Cagayan | C9: 77th Infantry Batallion Phil. Army, Capissayan Based | D9: 135 pcs. Red/White Lauan lumber/ flitches | E9: 5.17 | F9: =37759.2+22459.8 -> 60219 | G9: 1 unit power chainsaw | H9: CENRO Compound | I9: Under administrative confiscation proceedings
A10: January 28, 2019 | B10: San Mariano, Lal-lo, Cagayan | C10: PNP Lal-lo & DENR Personnel | D10: 39 pcs. Gmelina flitches | E10: 0.34 | F10: 4350.24 | H10: CENRO Compound | I10: Apprehended by virtue of Search Warrant issued by Judge Catherine Bangi-Allas, MTC Branch 1, Lal-lo, Cagayan on Jan. 24, 2019. A case was filed thru against Angel Balas thru inquest proceedings on January 28, 2019 at PPO Aparri, Cag docketed under NPS No. II-02a-INQ-19A-00023 w/ Criminal Case No. II-14613.
D11: 3 pcs. Narra planks | E11: 0.41 | F11: 55000
A12: January 28, 2019 | B12: Smart Gonzaga | C12: PNP Gonzaga | D12: 24 pcs. White Lauan lumber | E12: 0.13 | F12: 3733.24 | G12: 1 unit Honda TMX Motorcycle w/ sidecar | H12: CENRO Compound | I12: A case was filed against Quirino Camiling thru inquest proceedings at PPO Aparri on January 29, 2019 docketed under NPS-II-02a-INQ-19A-00026 w/ Criminal Case No. II.14615
